Workbook

Sheet Orders
AB1: Номер заказа | AC1: Адрес получателя | AF1: Необходимые свойства машины | AG1: Опциональные теги | AI1: Приоритет выполнения заказа | AL1: Временное окно * | AN1: Штраф | AO1: Жесткое временное окно, TRUE/FALSE | AP1: Вес (брутто), кг | AQ1: Кол-во занимаемых мест | AR1: Тип точки (pickup/delivery/garage/drop_off) | AS1: Время загрузки заказа на складе | AT1: Время готовности заказа на складе | AU1: Привязка к складу | AV1: Тип совместимости с другими заказами | BB1: Время обслуживания *
A2: - | B2: АМ | C2: №п/п | D2: № маг | E2: телефон | F2: Наименование получателя | G2: отд | H2: 09+12 | I2: 11 | J2: время подачи а/м | K2: Маршрут | L2: грзчк | M2: время прибытия в маг | N2: Рейс | O2: порядок | P2: Город | Q2: Адрес | R2: ФИО водителя | S2: В/У водителя | T2: Телефон водителя | U2: Марка автомобиля | V2: Гос.номер автомобиля | W2: Свид. Регистрации автомобиля | X2: Тип ТС | Y2: Грузоподъемность ТС | Z2: Тр.Компания | AA2: кол-во паллет | AD2: Широта | AE2: Долгота | AG2: 1 | AJ2: начало приёмки | AK2: конец приёмки | AM2: НОМЕР ЗОНЫ | AN2: За недоставку | AW2: Сравнение запланир времени и времени открытия маг | AY2: Категория маг | BA2: Наименование получателя | BB2: на адрес, сек | BC2: на заказ, сек | BE2: 29-11 | BF2: 30-11 | BG2: 01-12 | BH2: 15-12 | BI2: 16-12 | BJ2: 17-12 | BK2: 18-12
A3: comments | B3: comments | C3: comments | D3: ref | E3: phone | F3: title | G3: comments | H3: comments | I3: comments | J3: comments | K3: comments | L3: comments | M3: comments | N3: comments | O3: comments | P3: comments | Q3: comments | R3: comments | S3: comments | T3: comments | U3: comments | V3: comments | W3: comments | X3: comments | Y3: comments | Z3: comments | AA3: comments | AB3: id | AC3: address | AD3: point.lat | AE3: point.lon | AF3: required_tags | AG3: optional_tags.0.tag | AH3: optional_tags.0.value | AI3: sequence_order | AJ3: comments | AK3: comments | AL3: time_window | AM3: comments | AN3: penalty.drop | AO3: hard_window | AP3: shipment_size.weight_kg | AQ3: shipment_size.units | AR3: type | AS3: depot_duration_s | AT3: depot_ready_time | AU3: depot_id | AV3: load_types | AW3: comments | AX3: comments | AY3: comments | AZ3: comments | BA3: comments | BB3: shared_service_duration_s | BC3: service_duration_s | BE3: comments | BF3: comments | BG3: comments | BH3: comments | BI3: comments | BJ3: comments | BK3: comments | BL3: comments
A4: 0 | B4: 1 | C4: 2 | D4: 3 | E4: 4 | F4: 5 | G4: 6 | H4: 7 | I4: 8 | J4: 9 | K4: 10 | L4: 11 | M4: 12 | N4: 13 | O4: 14 | P4: 15 | Q4: 16 | R4: 17 | S4: 18 | T4: 19 | U4: 20 | V4: 21 | W4: 22 | X4: 23 | Y4: 24 | Z4: 25 | AA4: 26 | AB4: 27 | AC4: 28 | AD4: 29 | AE4: 30 | AF4: 31 | AG4: 32 | AH4: 33 | AI4: 34 | AJ4: 35 | AK4: 36 | AL4: 37 | AM4: 38 | AN4: 39 | AO4: 40 | AP4: 41 | AQ4: 42 | AR4: 43 | AS4: 44 | AT4: 45 | AU4: 46 | AV4: 47 | AW4: 48 | AX4: 49 | AY4: 50 | AZ4: 51 | BA4: 52 | BB4: 53 | BC4: 54 | BD4: 55 | BE4: 56 | BF4: 57 | BG4: 58 | BH4: 59 | BI4: 60 | BJ4: 61 | BK4: 62 | BL4: 63 | BM4: 64 | BN4: 65
C5: 460 | D5: 7009 | E5: 4009 | F5: МОСКОВСКИЙ-1-МКРН-158 | G5: АМ | H5: 9.8 | I5: 3.22 | J5: 04:00 | K5: АВС01_1 | L5: 2 | M5: 09:01:13 | N5: 1 | O5: 1 | P5: Московский | Q5: 1-й мкрн, д.158 | R5: Карасев Павел Евгеньевич | S5: 9922850884 | T5: 89001430044 | U5: ФОРД | V5: Н647МК799 | W5: 9937116734 | X5: Грузовой фургон | Y5: 3Т | Z5: авс | AA5: 8 | AB5: F460 | AC5: Московский, 1-й мкрн, д.158 | AF5: 12П, 2Г | AI5: 2 | AJ5: 09:00 | AK5: 0.54166667 | AL5: =CONCATENATE(TEXT(AJ5,"ЧЧ:ММ")," ","-"," ",TEXT(AK5,"ЧЧ:ММ")) -> 09:00 - 13:00 | AM5: 6 | AN5: =IF(AP5>1000,(AP5*320),300000) -> 300000 | AO5: TRUE | AP5: =H5*20+I5*20 -> 260.4 | AQ5: =IF(AP5>520,ROUNDUP(((H5*20)/560+(I5*20)/550),0),IF(SUM(H5:I5)=0,0,IF(AP5<255,1,ROUND(((H5*20)/520+(I5*20)/450),0)))) -> 1 | AR5: delivery | AW5: =IF(TIMEVALUE(M5)<TIMEVALUE(AJ5),AJ5,M5) -> 09:01:13 | AY5: 1 | BA5: =F5 -> МОСКОВСКИЙ-1-МКРН-158 | BB5: =AP5*4.6+10*60 -> 1797.84 | BE5: -16.558 | BG5: 9.626 | BH5: 16.526667 | BJ5: 6.4353333 | BK5: 61.835333 | BL5: МОСКОВСКИЙ_1_МКРН-158 Т/ЗАЛ
C6: 482 | D6: 877 | E6: 4877 | F6: ТРОИЦК-СОЛНЕЧНАЯ-9 | G6: АМР | H6: 7.61 | I6: 3.92 | K6: АВС01_1 | M6: 10:11:59 | N6: 1 | O6: 2 | P6: Троицк | Q6: ул.Солнечная 9 | R6: Карасев Павел Евгеньевич | S6: 9922850884 | T6: 89001430044 | U6: ФОРД | V6: Н647МК799 | W6: 9937116734 | X6: Грузовой фургон | Y6: 3Т | Z6: авс | AA6: 8 | AB6: F482 | AC6: Троицк, ул.Солнечная 9 | AF6: 14П | AI6: 2 | AJ6: =IF((WEEKDAY(TODAY(),2))=6,"10:00","09:30") -> 09:30 | AK6: 0.54166667 | AL6: =CONCATENATE(TEXT(AJ6,"ЧЧ:ММ")," ","-"," ",TEXT(AK6,"ЧЧ:ММ")) -> 09:30 - 13:00 | AM6: 5 | AN6: =IF(AP6>1000,(AP6*320),300000) -> 300000 | AO6: TRUE | AP6: =H6*20+I6*20 -> 230.6 | AQ6: =IF(AP6>520,ROUNDUP(((H6*20)/560+(I6*20)/550),0),IF(SUM(H6:I6)=0,0,IF(AP6<255,1,ROUND(((H6*20)/520+(I6*20)/450),0)))) -> 1 | AR6: delivery | AW6: =IF(TIMEVALUE(M6)<TIMEVALUE(AJ6),AJ6,M6) -> 10:11:59 | AY6: 1 | BA6: =F6 -> ТРОИЦК-СОЛНЕЧНАЯ-9 | BB6: =AP6*3+10*60 -> 1291.8 | BK6: 18.873333 | BL6: Троицк_Солнечная-9 т/зал
C7: 475 | D7: 7094 | E7: 4094 | F7: СОСЕНСКОЕ-ФИТАРЕВСКАЯ-6 | G7: АМ | H7: 25.24 | I7: 8.71 | K7: АВС01_1 | M7: 11:08:29 | N7: 1 | O7: 3 | P7: Москва | Q7: Сосенское,Коммунарка,Фитаревская ул., д.6 | R7: Карасев Павел Евгеньевич | S7: 9922850884 | T7: 89001430044 | U7: ФОРД | V7: Н647МК799 | W7: 9937116734 | X7: Грузовой фургон | Y7: 3Т | Z7: авс | AA7: 8 | AB7: F475 | AC7: улица Фитаревская, д.6, посёлок Коммунарка, Москва | AF7: 8П | AI7: 2 | AJ7: 09:00 | AK7: 0.75 | AL7: =CONCATENATE(TEXT(AJ7,"ЧЧ:ММ")," ","-"," ",TEXT(AK7,"ЧЧ:ММ")) -> 09:00 - 18:00 | AM7: 5 | AN7: =IF(AP7>1000,(AP7*320),300000) -> 300000 | AO7: TRUE | AP7: =H7*20+I7*20 -> 679 | AQ7: =IF(AP7>520,ROUNDUP(((H7*20)/560+(I7*20)/550),0),IF(SUM(H7:I7)=0,0,IF(AP7<255,1,ROUND(((H7*20)/520+(I7*20)/450),0)))) -> 2 | AR7: delivery | AW7: =IF(TIMEVALUE(M7)<TIMEVALUE(AJ7),AJ7,M7) -> 11:08:29 | AY7: 3 | BA7: =F7 -> СОСЕНСКОЕ-ФИТАРЕВСКАЯ-6 | BB7: =AP7*3.7+10*60 -> 3112.3 | BL7: ФИТАРЕВСКАЯ-6 Т/ЗАЛ
C8: 490 | D8: 7243 | E8: 4243 | F8: ПРОФСОЮЗНАЯ-152К1 | G8: АМ | H8: 17.35 | I8: 7.24 | K8: АВС01_1 | L8: 2 | M8: 12:19:49 | N8: 1 | O8: 4 | P8: Москва | Q8: Профсоюзная ул., д.152, к.1 | R8: Карасев Павел Евгеньевич | S8: 9922850884 | T8: 89001430044 | U8: ФОРД | V8: Н647МК799 | W8: 9937116734 | X8: Грузовой фургон | Y8: 3Т | Z8: авс | AA8: 8 | AB8: F490 | AC8: Москва, Профсоюзная ул., д.152, к.1 | AF8: 8П | AI8: 2 | AJ8: 09:30 | AK8: 0.54166667 | AL8: =CONCATENATE(TEXT(AJ8,"ЧЧ:ММ")," ","-"," ",TEXT(AK8,"ЧЧ:ММ")) -> 09:30 - 13:00 | AM8: 5 | AN8: =IF(AP8>1000,(AP8*320),300000) -> 300000 | AO8: TRUE | AP8: =H8*20+I8*20 -> 491.8 | AQ8: =IF(AP8>520,ROUNDUP(((H8*20)/560+(I8*20)/550),0),IF(SUM(H8:I8)=0,0,IF(AP8<255,1,ROUND(((H8*20)/520+(I8*20)/450),0)))) -> 1 | AR8: delivery | AW8: =IF(TIMEVALUE(M8)<TIMEVALUE(AJ8),AJ8,M8) -> 12:19:49 | AY8: 1 | BA8: =F8 -> ПРОФСОЮЗНАЯ-152К1 | BB8: =AP8*3.5+10*60 -> 2321.3 | BF8: -13.006667 | BJ8: -6.5833333 | BL8: ПРОФСОЮЗНАЯ-152 Т/ЗАЛ
C9: 80 | D9: 25935 | E9: 4935 | F9: САПРОНОВО-ЦЕНТРАЛЬНЫЙ-КВ-Л-1 | G9: АМР | H9: 40.86 | I9: 18.59 | K9: АВС01_1 | M9: 13:41:05 | N9: 1 | O9: 5 | P9: Ленинский г.о. | Q9: дер.Сапроново,мкр.Купелинка,кв.Центральный,д.1 | R9: Карасев Павел Евгеньевич | S9: 9922850884 | T9: 89001430044 | U9: ФОРД | V9: Н647МК799 | W9: 9937116734 | X9: Грузовой фургон | Y9: 3Т | Z9: авс | AA9: 8 | AB9: F80 | AC9: Ленинский г.о., дер.Сапроново,мкр.Купелинка,кв.Центральный,д.1 | AD9: 55.531875 | AE9: 37.721883 | AF9: 8П | AI9: 2 | AJ9: =IF((WEEKDAY(TODAY(),2))=6,"10:00","09:00") -> 09:00 | AK9: =IF(AP9>2000,"15:00",IF(AP9<1000,"16:30","16:00")) -> 16:00 | AL9: =CONCATENATE(TEXT(AJ9,"ЧЧ:ММ")," ","-"," ",TEXT(AK9,"ЧЧ:ММ")) -> 09:00 - 16:00 | AM9: 4 | AN9: =IF(AP9>1000,(AP9*320),300000) -> 380480 | AO9: TRUE | AP9: =H9*20+I9*20 -> 1189 | AQ9: =IF(AP9>520,ROUNDUP(((H9*20)/560+(I9*20)/550),0),IF(SUM(H9:I9)=0,0,IF(AP9<255,1,ROUND(((H9*20)/520+(I9*20)/450),0)))) -> 3 | AR9: delivery | AW9: =IF(TIMEVALUE(M9)<TIMEVALUE(AJ9),AJ9,M9) -> 13:41:05 | AY9: 2 | BA9: =F9 -> САПРОНОВО-ЦЕНТРАЛЬНЫЙ-КВ-Л-1 | BB9: =AP9*4.5+10*60 -> 5950.5 | BL9: Сапроново_Центальный_кв-1
C10: 24 | D10: 7045 | E10: 4045 | F10: БИРЮЛЕВСКАЯ-49 | G10: АМ | H10: 19.52 | I10: 3.31 | J10: 04:00 | K10: АВС02_1 | M10: 09:00 | N10: 1 | O10: 1 | P10: Москва | Q10: Бирюлевская ул, д.49 | R10: Андреев Николай Евгеньевич | S10: 7738771539 | T10: 89775647750 | U10: ИВЕКО | V10: У 011 ОН 799 | W10: 9941098942 | X10: Грузовой фургон | Y10: 3Т | Z10: авс | AA10: 8 | AB10: F24 | AC10: Москва, Бирюлевская ул, д.49 | AD10: 55.584115 | AE10: 37.676394 | AF10: 12П | AI10: 2 | AJ10: 09:00 | AK10: 0.54166667 | AL10: =CONCATENATE(TEXT(AJ10,"ЧЧ:ММ")," ","-"," ",TEXT(AK10,"ЧЧ:ММ")) -> 09:00 - 13:00 | AM10: 5 | AN10: =IF(AP10>1000,(AP10*320),300000) -> 300000 | AO10: TRUE | AP10: =H10*20+I10*20 -> 456.6 | AQ10: =IF(AP10>520,ROUNDUP(((H10*20)/560+(I10*20)/550),0),IF(SUM(H10:I10)=0,0,IF(AP10<255,1,ROUND(((H10*20)/520+(I10*20)/450),0)))) -> 1 | AR10: delivery | AW10: =IF(TIMEVALUE(M10)<TIMEVALUE(AJ10),AJ10,M10) -> 09:00 | AY10: 1 | BA10: =F10 -> БИРЮЛЕВСКАЯ-49 | BB10: =AP10*3.5+10*60 -> 2198.1 | BF10: 3.135 | BJ10: 15.845 | BL10: БИРЮЛЕВСКАЯ-49 Т/ЗАЛ
C11: 10 | D11: 918 | E11: 4918 | F11: ЯСЕНЕВАЯ-12К1 | G11: АМ | H11: 29.47 | I11: 8.29 | K11: АВС02_1 | M11: 09:53:30 | N11: 1 | O11: 2 | P11: Москва | Q11: Ясеневая ул., д.12, кор.1 | R11: Андреев Николай Евгеньевич | S11: 7738771539 | T11: 89775647750 | U11: ИВЕКО | V11: У 011 ОН 799 | W11: 9941098942 | X11: Грузовой фургон | Y11: 3Т | Z11: авс | AA11: 8 | AB11: F10 | AC11: Москва, Ясеневая ул., д.12, кор.1 | AF11: 12П | AI11: 2 | AJ11: 09:30 | AK11: 0.54166667 | AL11: =CONCATENATE(TEXT(AJ11,"ЧЧ:ММ")," ","-"," ",TEXT(AK11,"ЧЧ:ММ")) -> 09:30 - 13:00 | AM11: 4 | AN11: =IF(AP11>1000,(AP11*320),300000) -> 300000 | AO11: TRUE | AP11: =H11*20+I11*20 -> 755.2 | AQ11: =IF(AP11>520,ROUNDUP(((H11*20)/560+(I11*20)/550),0),IF(SUM(H11:I11)=0,0,IF(AP11<255,1,ROUND(((H11*20)/520+(I11*20)/450),0)))) -> 2 | AR11: delivery | AW11: =IF(TIMEVALUE(M11)<TIMEVALUE(AJ11),AJ11,M11) -> 09:53:30 | AY11: 1 | BA11: =F11 -> ЯСЕНЕВАЯ-12К1 | BB11: =AP11*3.5+10*60 -> 3243.2 | BH11: -6.7916667 | BL11: ЯСЕНЕВАЯ-12 Т/ЗАЛ
C12: 8 | D12: 803 | E12: 4803 | F12: КАШИРСКОЕ-Ш-65К1 | G12: АМ | H12: 20.8 | I12: 8.46 | K12: АВС02_1 | M12: 10:53:50 | N12: 1 | O12: 3 | P12: Москва | Q12: Каширское шоссе, д.65, кор.1 | R12: Андреев Николай Евгеньевич | S12: 7738771539 | T12: 89775647750 | U12: ИВЕКО | V12: У 011 ОН 799 | W12: 9941098942 | X12: Грузовой фургон | Y12: 3Т | Z12: авс | AA12: 8 | AB12: F8 | AC12: Москва, Каширское шоссе, д.65, кор.1 | AF12: 8П | AI12: 2 | AJ12: 09:00 | AK12: =IF((WEEKDAY(TODAY(),2))=4,"13:00","16:00") -> 16:00 | AL12: =CONCATENATE(TEXT(AJ12,"ЧЧ:ММ")," ","-"," ",TEXT(AK12,"ЧЧ:ММ")) -> 09:00 - 16:00 | AM12: 4 | AN12: =IF(AP12>1000,(AP12*320),300000) -> 300000 | AO12: TRUE | AP12: =H12*20+I12*20 -> 585.2 | AQ12: =IF(AP12>520,ROUNDUP(((H12*20)/560+(I12*20)/550),0),IF(SUM(H12:I12)=0,0,IF(AP12<255,1,ROUND(((H12*20)/520+(I12*20)/450),0)))) -> 2 | AR12: delivery | AW12: =IF(TIMEVALUE(M12)<TIMEVALUE(AJ12),AJ12,M12) -> 10:53:50 | AY12: 2 | BA12: =F12 -> КАШИРСКОЕ-Ш-65К1 | BB12: =AP12*4+10*60 -> 2940.8 | BI12: -0.48333333 | BL12: КАШИРСКОЕ_Ш 65/1 Т/ЗАЛ
C13: 13 | D13: 257112 | E13: 4112 | F13: МИСАЙЛОВО-ПРИГОРОДНОЕ-Ш-7 | G13: АМР | H13: 19.11 | I13: 16.13 | K13: АВС02_1 | M13: 12:10:30 | N13: 1 | O13: 4 | P13: г.Видное | Q13: дер.Мисайлово, ш.Пригородное, д.7 | R13: Андреев Николай Евгеньевич | S13: 7738771539 | T13: 89775647750 | U13: ИВЕКО | V13: У 011 ОН 799 | W13: 9941098942 | X13: Грузовой фургон | Y13: 3Т | Z13: авс | AA13: 8 | AB13: F13 | AC13: Мос.обл., дер.Мисайлово, Пригородное ш., д.7 | AF13: 12П | AI13: 2 | AJ13: =IF((WEEKDAY(TODAY(),2))=6,"10:00","09:00") -> 09:00 | AK13: =IF(AP13>2000,"15:00",IF(AP13<1000,"16:30","16:00")) -> 16:30 | AL13: =CONCATENATE(TEXT(AJ13,"ЧЧ:ММ")," ","-"," ",TEXT(AK13,"ЧЧ:ММ")) -> 09:00 - 16:30 | AM13: 4 | AN13: =IF(AP13>1000,(AP13*320),300000) -> 300000 | AO13: TRUE | AP13: =H13*20+I13*20 -> 704.8 | AQ13: =IF(AP13>520,ROUNDUP(((H13*20)/560+(I13*20)/550),0),IF(SUM(H13:I13)=0,0,IF(AP13<255,1,ROUND(((H13*20)/520+(I13*20)/450),0)))) -> 2 | AR13: delivery | AW13: =IF(TIMEVALUE(M13)<TIMEVALUE(AJ13),AJ13,M13) -> 12:10:30 | AY13: 2 | BA13: =F13 -> МИСАЙЛОВО-ПРИГОРОДНОЕ-Ш-7 | BB13: =AP13*3.5+10*60 -> 3066.8 | BL13: ВИДНОЕ_ПРИГОРОДНОЕ_Ш-7
C14: 3 | D14: 776 | E14: 4776 | F14: НОВОЧЕРКАССКИЙ-Б-Р-55 | G14: АМ | H14: 20.68 | I14: 1.72 | K14: АВС02_1 | M14: 13:38:18 | N14: 1 | O14: 5 | P14: Москва | Q14: Новочеркасский бульв., д.55 | R14: Андреев Николай Евгеньевич | S14: 7738771539 | T14: 89775647750 | U14: ИВЕКО | V14: У 011 ОН 799 | W14: 9941098942 | X14: Грузовой фургон | Y14: 3Т | Z14: авс | AA14: 8 | AB14: F3 | AC14: Москва, Новочеркасский бульв., д.55 | AF14: 8П | AI14: 2 | AJ14: 09:00 | AK14: 0.54166667 | AL14: =CONCATENATE(TEXT(AJ14,"ЧЧ:ММ")," ","-"," ",TEXT(AK14,"ЧЧ:ММ")) -> 09:00 - 13:00 | AM14: 4 | AN14: =IF(AP14>1000,(AP14*320),300000) -> 300000 | AO14: TRUE | AP14: =H14*20+I14*20 -> 448 | AQ14: =IF(AP14>520,ROUNDUP(((H14*20)/560+(I14*20)/550),0),IF(SUM(H14:I14)=0,0,IF(AP14<255,1,ROUND(((H14*20)/520+(I14*20)/450),0)))) -> 1 | AR14: delivery | AW14: =IF(TIMEVALUE(M14)<TIMEVALUE(AJ14),AJ14,M14) -> 13:38:18 | AY14: 1 | BA14: =F14 -> НОВОЧЕРКАССКИЙ-Б-Р-55 | BB14: =AP14*3.5+10*60 -> 2168 | BH14: -2.46 | BJ14: 48.43 | BL14: НОВОЧЕРКАССКИЙ_Б_Р-55 Т/ЗАЛ
C15: 343 | D15: 25953 | E15: 4953 | F15: МЫТИЩИ-АК-КАРГИНА-23А | G15: АМР | H15: 30.99 | I15: 7.32 | J15: 04:00 | K15: АВС03_1 | M15: 09:30 | N15: 1 | O15: 1 | P15: Мытищи | Q15: ул. Академика Каргина, д.23А | R15: Королев Владимир Николаевич | S15: 9944246048 | T15: 89773475755 | U15: ИВЕКО | V15: Е 248 РВ 799 | W15: 9943505322 | X15: Грузовой фургон | Y15: 3Т | Z15: авс | AA15: 8 | AB15: F343 | AC15: Мытищи, ул. Академика Каргина, д.23А | AF15: 12П | AI15: 2 | AJ15: =IF((WEEKDAY(TODAY(),2))=6,"10:00","09:30") -> 09:30 | AK15: =IF(AP15>2000,"15:00",IF(AP15<1000,"16:30","16:00")) -> 16:30 | AL15: =CONCATENATE(TEXT(AJ15,"ЧЧ:ММ")," ","-"," ",TEXT(AK15,"ЧЧ:ММ")) -> 09:30 - 16:30 | AM15: 2 | AN15: =IF(AP15>1000,(AP15*320),300000) -> 300000 | AO15: TRUE | AP15: =H15*20+I15*20 -> 766.2 | AQ15: =IF(AP15>520,ROUNDUP(((H15*20)/560+(I15*20)/550),0),IF(SUM(H15:I15)=0,0,IF(AP15<255,1,ROUND(((H15*20)/520+(I15*20)/450),0)))) -> 2 | AR15: delivery | AW15: =IF(TIMEVALUE(M15)<TIMEVALUE(AJ15),AJ15,M15) -> 09:30 | AY15: 2 | BA15: =F15 -> МЫТИЩИ-АК-КАРГИНА-23А | BB15: =AP15*3.8+10*60 -> 3511.56 | BL15: Мытищи_Ак_Каргина-23а
C16: 334 | D16: 257161 | E16: 4161 | F16: 1-СТРЕЛКОВЫЙ-ПЕР-3 | G16: АМР | H16: 17.61 | I16: 8.51 | K16: АВС03_1 | M16: 10:49:24 | N16: 1 | O16: 2 | P16: Мытищи | Q16: 1й Стрелковый пер., д.3 | R16: Королев Владимир Николаевич | S16: 9944246048 | T16: 89773475755 | U16: ИВЕКО | V16: Е 248 РВ 799 | W16: 9943505322 | X16: Грузовой фургон | Y16: 3Т | Z16: авс | AA16: 8 | AB16: F334 | AC16: Московская Область, г.о. Мытищи, г. Мытищи, 1-й Стрелковый пер.,д.3 | AF16: 12П | AI16: 2 | AJ16: =IF((WEEKDAY(TODAY(),2))=6,"10:00","09:30") -> 09:30 | AK16: 0.75 | AL16: =CONCATENATE(TEXT(AJ16,"ЧЧ:ММ")," ","-"," ",TEXT(AK16,"ЧЧ:ММ")) -> 09:30 - 18:00 | AM16: 2 | AN16: =IF(AP16>1000,(AP16*320),300000) -> 300000 | AO16: TRUE | AP16: =H16*20+I16*20 -> 522.4 | AQ16: =IF(AP16>520,ROUNDUP(((H16*20)/560+(I16*20)/550),0),IF(SUM(H16:I16)=0,0,IF(AP16<255,1,ROUND(((H16*20)/520+(I16*20)/450),0)))) -> 1 | AR16: delivery | AW16: =IF(TIMEVALUE(M16)<TIMEVALUE(AJ16),AJ16,M16) -> 10:49:24 | AY16: 3 | BA16: =F16 -> 1-СТРЕЛКОВЫЙ-ПЕР-3 | BB16: =AP16*3.5+10*60 -> 2428.4 | BL16: МЫТИЩИ_1_СТРЕЛКОВЫЙ-3
C17: 341 | D17: 25711 | E17: 4711 | F17: МЫТИЩИ-РОЖДЕСТВЕНСКАЯ-11 | G17: АМР | H17: 19.86 | I17: 12.76 | K17: АВС03_1 | M17: 11:56:41 | N17: 1 | O17: 3 | P17: Мытищи | Q17: Рождественская ул 11 | R17: Королев Владимир Николаевич | S17: 9944246048 | T17: 89773475755 | U17: ИВЕКО | V17: Е 248 РВ 799 | W17: 9943505322 | X17: Грузовой фургон | Y17: 3Т | Z17: авс | AA17: 8 | AB17: F341 | AC17: Мытищи, Рождественская ул 11 | AF17: 12П | AI17: 2 | AJ17: =IF((WEEKDAY(TODAY(),2))=6,"10:00","09:00") -> 09:00 | AK17: 0.54166667 | AL17: =CONCATENATE(TEXT(AJ17,"ЧЧ:ММ")," ","-"," ",TEXT(AK17,"ЧЧ:ММ")) -> 09:00 - 13:00 | AM17: 2 | AN17: =IF(AP17>1000,(AP17*320),300000) -> 300000 | AO17: TRUE | AP17: =H17*20+I17*20 -> 652.4 | AQ17: =IF(AP17>520,ROUNDUP(((H17*20)/560+(I17*20)/550),0),IF(SUM(H17:I17)=0,0,IF(AP17<255,1,ROUND(((H17*20)/520+(I17*20)/450),0)))) -> 2 | AR17: delivery | AW17: =IF(TIMEVALUE(M17)<TIMEVALUE(AJ17),AJ17,M17) -> 11:56:41 | AY17: 1 | BA17: =F17 -> МЫТИЩИ-РОЖДЕСТВЕНСКАЯ-11 | BB17: =AP17*3.5+10*60 -> 2883.4 | BF17: -27.166667 | BG17: 12.176667 | BL17: Мытищи_рождественская-11
C18: 336 | D18: 25682 | E18: 7682 | F18: МЫТИЩИ-КОЛПАКОВА-26 | G18: АМР | H18: 13.98 | I18: 3.99 | K18: АВС03_1 | M18: 13:01:30 | N18: 1 | O18: 4 | P18: Мытищи | Q18: ул.Колпакова, д.26 | R18: Королев Владимир Николаевич | S18: 9944246048 | T18: 89773475755 | U18: ИВЕКО | V18: Е 248 РВ 799 | W18: 9943505322 | X18: Грузовой фургон | Y18: 3Т | Z18: авс | AA18: 8 | AB18: F336 | AC18: Мытищи, ул.Колпакова, д.26 | AF18: 14П | AI18: 2 | AJ18: =IF((WEEKDAY(TODAY(),2))=6,"10:00","09:30") -> 09:30 | AK18: 0.75 | AL18: =CONCATENATE(TEXT(AJ18,"ЧЧ:ММ")," ","-"," ",TEXT(AK18,"ЧЧ:ММ")) -> 09:30 - 18:00 | AM18: 2 | AN18: =IF(AP18>1000,(AP18*320),300000) -> 300000 | AO18: TRUE | AP18: =H18*20+I18*20 -> 359.4 | AQ18: =IF(AP18>520,ROUNDUP(((H18*20)/560+(I18*20)/550),0),IF(SUM(H18:I18)=0,0,IF(AP18<255,1,ROUND(((H18*20)/520+(I18*20)/450),0)))) -> 1 | AR18: delivery | AW18: =IF(TIMEVALUE(M18)<TIMEVALUE(AJ18),AJ18,M18) -> 13:01:30 | AY18: 3 | BA18: =F18 -> МЫТИЩИ-КОЛПАКОВА-26 | BB18: =AP18*3.7+10*60 -> 1929.78 | BG18: -10.129667 | BH18: 8.0403333 | BJ18: 54.853 | BL18: Мытищи_колпакова-26
C19: 337 | D19: 25966 | E19: 4966 | F19: МЫТИЩИ-АСТРАХОВА-ПР-Т-2 | G19: АМР | H19: 21.38 | I19: 6.51 | K19: АВС03_1 | M19: 13:40:32 | N19: 1 | O19: 5 | P19: Мытищи | Q19: просп. Астрахова, д.2 | R19: Королев Владимир Николаевич | S19: 9944246048 | T19: 89773475755 | U19: ИВЕКО | V19: Е 248 РВ 799 | W19: 9943505322 | X19: Грузовой фургон | Y19: 3Т | Z19: авс | AA19: 8 | AB19: F337 | AC19: Мытищи, просп. Астрахова, д.2 | AF19: 12П | AI19: 2 | AJ19: =IF((WEEKDAY(TODAY(),2))=6,"10:00","09:30") -> 09:30 | AK19: 0.75 | AL19: =CONCATENATE(TEXT(AJ19,"ЧЧ:ММ")," ","-"," ",TEXT(AK19,"ЧЧ:ММ")) -> 09:30 - 18:00 | AM19: 2 | AN19: =IF(AP19>1000,(AP19*320),300000) -> 300000 | AO19: TRUE | AP19: =H19*20+I19*20 -> 557.8 | AQ19: =IF(AP19>520,ROUNDUP(((H19*20)/560+(I19*20)/550),0),IF(SUM(H19:I19)=0,0,IF(AP19<255,1,ROUND(((H19*20)/520+(I19*20)/450),0)))) -> 2 | AR19: delivery | AW19: =IF(TIMEVALUE(M19)<TIMEVALUE(AJ19),AJ19,M19) -> 13:40:32 | AY19: 3 | BA19: =F19 -> МЫТИЩИ-АСТРАХОВА-ПР-Т-2 | BB19: =AP19*3+10*60 -> 2273.4 | BH19: 13.45 | BL19: Мытищи_Астрахова-2
C20: 548 | D20: 25979 | E20: 4979 | F20: ЛЮБЕРЦЫ-КОМСОМОЛ-ПР-Т-16К2 | G20: АМР | H20: 25.33 | I20: 8 | J20: 04:00 | K20: АВС04_1 | M20: 11:21:03 | N20: 1 | O20: 1 | P20: Люберцы | Q20: Комсомольский просп., д.16, кор.2 | R20: Лящук Николай Сергеевич | S20: 9907625470 | T20: 89965336717 | U20: ИВЕКО | V20: А828ЕЕ799 | W20: 9972976650 | X20: Грузовой фургон | Y20: 3Т | Z20: авс | AA20: 8 | AB20: F548 | AC20: Люберцы, Комсомольский просп., д.16, кор.2 | AF20: 14П | AI20: 2 | AJ20: =IF((WEEKDAY(TODAY(),2))=6,"10:00","09:30") -> 09:30 | AK20: =IF(AP20>2000,"15:00",IF(AP20<1000,"16:30","16:00")) -> 16:30 | AL20: =CONCATENATE(TEXT(AJ20,"ЧЧ:ММ")," ","-"," ",TEXT(AK20,"ЧЧ:ММ")) -> 09:30 - 16:30 | AM20: 3 | AN20: =IF(AP20>1000,(AP20*320),300000) -> 300000 | AO20: TRUE | AP20: =H20*20+I20*20 -> 666.6 | AQ20: =IF(AP20>520,ROUNDUP(((H20*20)/560+(I20*20)/550),0),IF(SUM(H20:I20)=0,0,IF(AP20<255,1,ROUND(((H20*20)/520+(I20*20)/450),0)))) -> 2 | AR20: delivery | AW20: =IF(TIMEVALUE(M20)<TIMEVALUE(AJ20),AJ20,M20) -> 11:21:03 | AY20: 2 | BA20: =F20 -> ЛЮБЕРЦЫ-КОМСОМОЛ-ПР-Т-16К2 | BB20: =AP20*3.5+10*60 -> 2933.1 | BL20: Люберцы_Комсомольский-16
C21: 546 | D21: 25993 | E21: 4993 | F21: ЛЮБЕРЦЫ-ИНИЦИАТИВНАЯ-7В | G21: АМР | H21: 28.95 | I21: 9.13 | K21: АВС04_1 | M21: 12:18:18 | N21: 1 | O21: 2 | P21: Люберцы | Q21: Инициативная ул., д.7В | R21: Лящук Николай Сергеевич | S21: 9907625470 | T21: 89965336717 | U21: ИВЕКО | V21: А828ЕЕ799 | W21: 9972976650 | X21: Грузовой фургон | Y21: 3Т | Z21: авс | AA21: 8 | AB21: F546 | AC21: Люберцы, Инициативная ул., д.7В | AF21: 14П | AI21: 2 | AJ21: =IF((WEEKDAY(TODAY(),2))=6,"10:00","09:30") -> 09:30 | AK21: =IF(AP21>2000,"15:00",IF(AP21<1000,"16:30","16:00")) -> 16:30 | AL21: =CONCATENATE(TEXT(AJ21,"ЧЧ:ММ")," ","-"," ",TEXT(AK21,"ЧЧ:ММ")) -> 09:30 - 16:30 | AM21: 3 | AN21: =IF(AP21>1000,(AP21*320),300000) -> 300000 | AO21: TRUE | AP21: =H21*20+I21*20 -> 761.6 | AQ21: =IF(AP21>520,ROUNDUP(((H21*20)/560+(I21*20)/550),0),IF(SUM(H21:I21)=0,0,IF(AP21<255,1,ROUND(((H21*20)/520+(I21*20)/450),0)))) -> 2 | AR21: delivery | AW21: =IF(TIMEVALUE(M21)<TIMEVALUE(AJ21),AJ21,M21) -> 12:18:18 | AY21: 2 | BA21: =F21 -> ЛЮБЕРЦЫ-ИНИЦИАТИВНАЯ-7В | BB21: =AP21*3+10*60 -> 2884.8 | BG21: -0.81666667 | BH21: -27.08 | BJ21: 8.16 | BL21: Люберцы_Инициативная-7в
C22: 547 | D22: 25973 | E22: 4973 | F22: ЛЮБЕРЦЫ-8-МАРТА-18К1 | G22: АМР | H22: 14.19 | I22: 10.49 | K22: АВС04_1 | L22: 2 | M22: 13:15:57 | N22: 1 | O22: 3 | P22: Люберцы | Q22: ул.8 марта, д.18, кор.1 | R22: Лящук Николай Сергеевич | S22: 9907625470 | T22: 89965336717 | U22: ИВЕКО | V22: А828ЕЕ799 | W22: 9972976650 | X22: Грузовой фургон | Y22: 3Т | Z22: авс | AA22: 8 | AB22: F547 | AC22: Люберцы, ул.8 марта, д.18, кор.1 | AF22: 8П,2Г | AI22: 2 | AJ22: =IF((WEEKDAY(TODAY(),2))=6,"10:00","09:30") -> 09:30 | AK22: 0.58333333 | AL22: =CONCATENATE(TEXT(AJ22,"ЧЧ:ММ")," ","-"," ",TEXT(AK22,"ЧЧ:ММ")) -> 09:30 - 14:00 | AM22: 3 | AN22: =IF(AP22>1000,(AP22*320),300000) -> 300000 | AO22: TRUE | AP22: =H22*20+I22*20 -> 493.6 | AQ22: =IF(AP22>520,ROUNDUP(((H22*20)/560+(I22*20)/550),0),IF(SUM(H22:I22)=0,0,IF(AP22<255,1,ROUND(((H22*20)/520+(I22*20)/450),0)))) -> 1 | AR22: delivery | AW22: =IF(TIMEVALUE(M22)<TIMEVALUE(AJ22),AJ22,M22) -> 13:15:57 | AY22: 2 | BA22: =F22 -> ЛЮБЕРЦЫ-8-МАРТА-18К1 | BB22: =AP22*4.1+10*60 -> 2623.76 | BF22: -2.9476667 | BG22: -0.39433333 | BH22: -26.614667 | BJ22: -3.985 | BL22: Люберцы_8 Марта-18
C23: 556 | D23: 25995 | E23: 4995 | F23: ЛЮБЕРЦЫ-КАМОВА-5К1 | G23: АМР | H23: 18.28 | I23: 7.67 | K23: АВС04_1 | M23: 14:25:52 | N23: 1 | O23: 4 | P23: Люберцы | Q23: ул.Камова д.5 к.1 | R23: Лящук Николай Сергеевич | S23: 9907625470 | T23: 89965336717 | U23: ИВЕКО | V23: А828ЕЕ799 | W23: 9972976650 | X23: Грузовой фургон | Y23: 3Т | Z23: авс | AA23: 8 | AB23: F556 | AC23: Люберцы, ул.Камова д.5 к.1 | AF23: 8П | AI23: 2 | AJ23: =IF((WEEKDAY(TODAY(),2))=6,"10:00","09:30") -> 09:30 | AK23: =IF(AP23>2000,"15:00",IF(AP23<1000,"16:30","16:00")) -> 16:30 | AL23: =CONCATENATE(TEXT(AJ23,"ЧЧ:ММ")," ","-"," ",TEXT(AK23,"ЧЧ:ММ")) -> 09:30 - 16:30 | AM23: 3 | AN23: =IF(AP23>1000,(AP23*320),300000) -> 300000 | AO23: TRUE | AP23: =H23*20+I23*20 -> 519 | AQ23: =IF(AP23>520,ROUNDUP(((H23*20)/560+(I23*20)/550),0),IF(SUM(H23:I23)=0,0,IF(AP23<255,1,ROUND(((H23*20)/520+(I23*20)/450),0)))) -> 1 | AR23: delivery | AW23: =IF(TIMEVALUE(M23)<TIMEVALUE(AJ23),AJ23,M23) -> 14:25:52 | AY23: 2 | BA23: =F23 -> ЛЮБЕРЦЫ-КАМОВА-5К1 | BB23: =AP23*3+10*60 -> 2157 | BF23: 1.0033333 | BG23: 7.95 | BH23: 24.14 | BL23: Люберцы_Камова-5
C24: 563 | D24: 25914 | E24: 4914 | F24: САВВИНО-СПАССКИЙ-Б-Р-1 | G24: АМР | H24: 18.59 | I24: 3.31 | K24: АВС04_1 | M24: 15:41:18 | N24: 1 | O24: 5 | P24: Балашиха | Q24: мкр.Саввино,Спасский б-р д.1 | R24: Лящук Николай Сергеевич | S24: 9907625470 | T24: 89965336717 | U24: ИВЕКО | V24: А828ЕЕ799 | W24: 9972976650 | X24: Грузовой фургон | Y24: 3Т | Z24: авс | AA24: 8 | AB24: F563 | AC24: Балашиха, г.о.Балашиха,мкр.Саввино,Спасский б-р д.1 | AF24: 12П | AI24: 2 | AJ24: =IF((WEEKDAY(TODAY(),2))=6,"10:00","09:00") -> 09:00 | AK24: =IF(AP24>2000,"15:00",IF(AP24<1000,"16:30","16:00")) -> 16:30 | AL24: =CONCATENATE(TEXT(AJ24,"ЧЧ:ММ")," ","-"," ",TEXT(AK24,"ЧЧ:ММ")) -> 09:00 - 16:30 | AM24: 3 | AN24: =IF(AP24>1000,(AP24*320),300000) -> 300000 | AO24: TRUE | AP24: =H24*20+I24*20 -> 438 | AQ24: =IF(AP24>520,ROUNDUP(((H24*20)/560+(I24*20)/550),0),IF(SUM(H24:I24)=0,0,IF(AP24<255,1,ROUND(((H24*20)/520+(I24*20)/450),0)))) -> 1 | AR24: delivery | AW24: =IF(TIMEVALUE(M24)<TIMEVALUE(AJ24),AJ24,M24) -> 15:41:18 | AY24: 2 | BA24: =F24 -> САВВИНО-СПАССКИЙ-Б-Р-1 | BB24: =AP24*3+10*60 -> 1914 | BL24: Балашиха_Спасский-1
C25: 550 | D25: 25929 | E25: 4929 | F25: ЛЮБЕРЦЫ-ВЕСЕННЯЯ-12 | G25: АМР | H25: 32.99 | I25: 10.91 | J25: 04:30 | K25: АВС05_1 | M25: 09:30 | N25: 1 | O25: 1 | P25: Люберцы | Q25: Весенняя ул, 12 | R25: Краснов Александр Николаевич | S25: 9908654881 | T25: 89771346704 | U25: ФОРД | V25: К183АМ977 | W25: 9947787826 | X25: Грузовой фургон | Y25: 3Т | Z25: авс | AA25: 8 | AB25: F550 | AC25: Люберцы, Весенняя ул, 12 | AF25: 8П | AI25: 2 | AJ25: =IF((WEEKDAY(TODAY(),2))=6,"10:00","09:30") -> 09:30 | AK25: =IF(AP25>2000,"15:00",IF(AP25<1000,"16:30","16:00")) -> 16:30 | AL25: =CONCATENATE(TEXT(AJ25,"ЧЧ:ММ")," ","-"," ",TEXT(AK25,"ЧЧ:ММ")) -> 09:30 - 16:30 | AM25: 3 | AN25: =IF(AP25>1000,(AP25*320),300000) -> 300000 | AO25: TRUE | AP25: =H25*20+I25*20 -> 878 | AQ25: =IF(AP25>520,ROUNDUP(((H25*20)/560+(I25*20)/550),0),IF(SUM(H25:I25)=0,0,IF(AP25<255,1,ROUND(((H25*20)/520+(I25*20)/450),0)))) -> 2 | AR25: delivery | AW25: =IF(TIMEVALUE(M25)<TIMEVALUE(AJ25),AJ25,M25) -> 09:30 | AY25: 2 | BA25: =F25 -> ЛЮБЕРЦЫ-ВЕСЕННЯЯ-12 | BB25: =AP25*3+10*60 -> 3234 | BF25: 7.1333333 | BL25: Люберцы_Весенняя-12
C26: 545 | D26: 903 | E26: 4903 | F26: НОВОКОСИНСКАЯ-13К2 | G26: АМР | H26: 49.15 | I26: 12.4 | K26: АВС05_1 | M26: 10:48:46 | N26: 1 | O26: 2 | P26: Москва | Q26: Новокосинская ул., 13 к 2 | R26: Краснов Александр Николаевич | S26: 9908654881 | T26: 89771346704 | U26: ФОРД | V26: К183АМ977 | W26: 9947787826 | X26: Грузовой фургон | Y26: 3Т | Z26: авс | AA26: 8 | AB26: F545 | AC26: Москва, Новокосинская ул., 13 к 2 | AF26: 12П | AI26: 2 | AJ26: =IF((WEEKDAY(TODAY(),2))=6,"10:00","09:00") -> 09:00 | AK26: =IF(AP26>2000,"15:00",IF(AP26<1000,"16:30","16:00")) -> 16:00 | AL26: =CONCATENATE(TEXT(AJ26,"ЧЧ:ММ")," ","-"," ",TEXT(AK26,"ЧЧ:ММ")) -> 09:00 - 16:00 | AM26: 3 | AN26: =IF(AP26>1000,(AP26*320),300000) -> 393920 | AO26: TRUE | AP26: =H26*20+I26*20 -> 1231 | AQ26: =IF(AP26>520,ROUNDUP(((H26*20)/560+(I26*20)/550),0),IF(SUM(H26:I26)=0,0,IF(AP26<255,1,ROUND(((H26*20)/520+(I26*20)/450),0)))) -> 3 | AR26: delivery | AW26: =IF(TIMEVALUE(M26)<TIMEVALUE(AJ26),AJ26,M26) -> 10:48:46 | AY26: 2 | BA26: =F26 -> НОВОКОСИНСКАЯ-13К2 | BB26: =AP26*3.3+10*60 -> 4662.3 | BF26: -28.824667 | BL26: НОВОКОСИНСКАЯ-13 Т/ЗАЛ
C27: 542 | D27: 25790 | E27: 4790 | F27: РЕУТОВ-ЧЕЛОМЕЯ-11 | G27: АМР | H27: 21.63 | I27: 8.86 | K27: АВС05_1 | M27: 12:18:24 | N27: 1 | O27: 3 | P27: Реутов | Q27: ул.Челомея, д.11 | R27: Краснов Александр Николаевич | S27: 9908654881 | T27: 89771346704 | U27: ФОРД | V27: К183АМ977 | W27: 9947787826 | X27: Грузовой фургон | Y27: 3Т | Z27: авс | AA27: 8 | AB27: F542 | AC27: Реутов, ул.Челомея, д.11 | AF27: 12П | AI27: 2 | AJ27: =IF((WEEKDAY(TODAY(),2))=6,"10:00","09:00") -> 09:00 | AK27: =IF(AP27>2000,"15:00",IF(AP27<1000,"16:30","16:00")) -> 16:30 | AL27: =CONCATENATE(TEXT(AJ27,"ЧЧ:ММ")," ","-"," ",TEXT(AK27,"ЧЧ:ММ")) -> 09:00 - 16:30 | AM27: 3 | AN27: =IF(AP27>1000,(AP27*320),300000) -> 300000 | AO27: TRUE | AP27: =H27*20+I27*20 -> 609.8 | AQ27: =IF(AP27>520,ROUNDUP(((H27*20)/560+(I27*20)/550),0),IF(SUM(H27:I27)=0,0,IF(AP27<255,1,ROUND(((H27*20)/520+(I27*20)/450),0)))) -> 2 | AR27: delivery | AW27: =IF(TIMEVALUE(M27)<TIMEVALUE(AJ27),AJ27,M27) -> 12:18:24 | AY27: 2 | BA27: =F27 -> РЕУТОВ-ЧЕЛОМЕЯ-11 | BB27: =AP27*3.3+10*60 -> 2612.34 | BK27: -4.8856667 | BL27: Реутов Челомея-11
C28: 532 | D28: 634 | E28: 7634 | F28: БУДЕННОГО-ПР-Т-30/8 | G28: АМ | H28: 6.79 | I28: 3.13 | K28: АВС05_1 | M28: 13:33:41 | N28: 1 | O28: 4 | P28: Москва | Q28: Буденного пр-т, д. 30/8 | R28: Краснов Александр Николаевич | S28: 9908654881 | T28: 89771346704 | U28: ФОРД | V28: К183АМ977 | W28: 9947787826 | X28: Грузовой фургон | Y28: 3Т | Z28: авс | AA28: 8 | AB28: F532 | AC28: Москва, Буденного пр-т, д. 30/8 | AF28: 12П | AI28: 2 | AJ28: 09:00 | AK28: 0.54166667 | AL28: =CONCATENATE(TEXT(AJ28,"ЧЧ:ММ")," ","-"," ",TEXT(AK28,"ЧЧ:ММ")) -> 09:00 - 13:00 | AM28: 3 | AN28: =IF(AP28>1000,(AP28*320),300000) -> 300000 | AO28: TRUE | AP28: =H28*20+I28*20 -> 198.4 | AQ28: =IF(AP28>520,ROUNDUP(((H28*20)/560+(I28*20)/550),0),IF(SUM(H28:I28)=0,0,IF(AP28<255,1,ROUND(((H28*20)/520+(I28*20)/450),0)))) -> 1 | AR28: delivery | AW28: =IF(TIMEVALUE(M28)<TIMEVALUE(AJ28),AJ28,M28) -> 13:33:41 | AY28: 1 | BA28: =F28 -> БУДЕННОГО-ПР-Т-30/8 | BB28: =AP28*3+10*60 -> 1195.2 | BK28: 15.813333 | BL28: БУДЕННОГО ПР-КТ Т/ЗАЛ
C29: 180 | D29: 945 | E29: 4945 | F29: СМОЛЬНАЯ-44 | G29: АМ | H29: 12.97 | I29: 11.34 | J29: 04:30 | K29: АВС06_1 | M29: 09:00 | N29: 1 | O29: 1 | P29: Москва | Q29: ул. Смольная 44 | R29: Петросян Ерванд Айказович | S29: 50ОУ637069 | T29: 89259050666 | U29: ФОРД | V29: К182АМ977 | W29: 9947787533 | X29: Грузовой фургон | Y29: 3Т | Z29: авс | AA29: 8 | AB29: F180 | AC29: Москва, ул. Смольная 44 | AD29: 55.869418 | AE29: 37.473360 | AF29: 12П | AI29: 2 | AJ29: 09:00 | AK29: 0.54166667 | AL29: =CONCATENATE(TEXT(AJ29,"ЧЧ:ММ")," ","-"," ",TEXT(AK29,"ЧЧ:ММ")) -> 09:00 - 13:00 | AM29: 2 | AN29: =IF(AP29>1000,(AP29*320),300000) -> 300000 | AO29: TRUE | AP29: =H29*20+I29*20 -> 486.2 | AQ29: =IF(AP29>520,ROUNDUP(((H29*20)/560+(I29*20)/550),0),IF(SUM(H29:I29)=0,0,IF(AP29<255,1,ROUND(((H29*20)/520+(I29*20)/450),0)))) -> 1 | AR29: delivery | AW29: =IF(TIMEVALUE(M29)<TIMEVALUE(AJ29),AJ29,M29) -> 09:00 | AY29: 1 | BA29: =F29 -> СМОЛЬНАЯ-44 | BB29: =AP29*3.5+10*60 -> 2301.7 | BE29: 46.968333 | BF29: -0.23333333 | BL29: СМОЛЬНАЯ-44 Т/ЗАЛ
C30: 159 | D30: 884 | E30: 4884 | F30: ИЛЬМЕНСКИЙ-ПР-Д-14К6 | G30: АМ | H30: 9.76 | I30: 5.65 | K30: АВС06_1 | M30: 10:03:40 | N30: 1 | O30: 2 | P30: Москва | Q30: Ильменский пр-д, д.14 к.6 | R30: Петросян Ерванд Айказович | S30: 50ОУ637069 | T30: 89259050666 | U30: ФОРД | V30: К182АМ977 | W30: 9947787533 | X30: Грузовой фургон | Y30: 3Т | Z30: авс | AA30: 8 | AB30: F159 | AC30: Москва, Ильменский пр-д, д.14 к.6 | AF30: 8П | AI30: 2 | AJ30: 08:30 | AK30: 0.45833333 | AL30: =CONCATENATE(TEXT(AJ30,"ЧЧ:ММ")," ","-"," ",TEXT(AK30,"ЧЧ:ММ")) -> 08:30 - 11:00 | AM30: 2 | AN30: =IF(AP30>1000,(AP30*320),300000) -> 300000 | AO30: TRUE | AP30: =H30*20+I30*20 -> 308.2 | AQ30: =IF(AP30>520,ROUNDUP(((H30*20)/560+(I30*20)/550),0),IF(SUM(H30:I30)=0,0,IF(AP30<255,1,ROUND(((H30*20)/520+(I30*20)/450),0)))) -> 1 | AR30: delivery | AW30: =IF(TIMEVALUE(M30)<TIMEVALUE(AJ30),AJ30,M30) -> 10:03:40 | AY30: 1 | BA30: =F30 -> ИЛЬМЕНСКИЙ-ПР-Д-14К6 | BB30: =AP30*3.5+10*60 -> 1678.7 | BE30: 0.185 | BF30: -6.9383333 | BI30: 10.673333 | BK30: -4.89 | BL30: ИЛЬМЕНСКИЙ_ПР_Д-14 Т/ЗАЛ
C31: 160 | D31: 923 | E31: 4923 | F31: ДЕГУНИНСКАЯ-3К2 | G31: АМ | H31: 24.49 | I31: 7.55 | K31: АВС06_1 | M31: 10:33:30 | N31: 1 | O31: 3 | P31: Москва | Q31: Дегунинская ул. 3 к 2 | R31: Петросян Ерванд Айказович | S31: 50ОУ637069 | T31: 89259050666 | U31: ФОРД | V31: К182АМ977 | W31: 9947787533 | X31: Грузовой фургон | Y31: 3Т | Z31: авс | AA31: 8 | AB31: F160 | AC31: Москва, Дегунинская ул. 3 к 2 | AF31: 12П | AI31: 2 | AJ31: 09:30 | AK31: =IF(AP31>2000,"15:00",IF(AP31<1000,"16:30","16:00")) -> 16:30 | AL31: =CONCATENATE(TEXT(AJ31,"ЧЧ:ММ")," ","-"," ",TEXT(AK31,"ЧЧ:ММ")) -> 09:30 - 16:30 | AM31: 2 | AN31: =IF(AP31>1000,(AP31*320),300000) -> 300000 | AO31: TRUE | AP31: =H31*20+I31*20 -> 640.8 | AQ31: =IF(AP31>520,ROUNDUP(((H31*20)/560+(I31*20)/550),0),IF(SUM(H31:I31)=0,0,IF(AP31<255,1,ROUND(((H31*20)/520+(I31*20)/450),0)))) -> 2 | AR31: delivery | AW31: =IF(TIMEVALUE(M31)<TIMEVALUE(AJ31),AJ31,M31) -> 10:33:30 | AY31: 2 | BA31: =F31 -> ДЕГУНИНСКАЯ-3К2 | BB31: =AP31*3.5+10*60 -> 2842.8 | BE31: -24.343333 | BG31: -18.851667 | BL31: ДЕГУНИНСКАЯ-32 Т/ЗАЛ
C32: 157 | D32: 7012 | E32: 4012 | F32: КОВИНСКОЕ-Ш-1К1 | G32: АМ | H32: 5.94 | I32: 1.77 | K32: АВС06_1 | M32: 11:26:37 | N32: 1 | O32: 4 | P32: Москва | Q32: Коровинское ш, д.1, кор.1 | R32: Петросян Ерванд Айказович | S32: 50ОУ637069 | T32: 89259050666 | U32: ФОРД | V32: К182АМ977 | W32: 9947787533 | X32: Грузовой фургон | Y32: 3Т | Z32: авс | AA32: 8 | AB32: F157 | AC32: Москва, Коровинское ш, д.1, кор.1 | AF32: 12П | AI32: 2 | AJ32: 09:30 | AK32: 0.75 | AL32: =CONCATENATE(TEXT(AJ32,"ЧЧ:ММ")," ","-"," ",TEXT(AK32,"ЧЧ:ММ")) -> 09:30 - 18:00 | AM32: 2 | AN32: =IF(AP32>1000,(AP32*320),300000) -> 300000 | AO32: TRUE | AP32: =H32*20+I32*20 -> 154.2 | AQ32: =IF(AP32>520,ROUNDUP(((H32*20)/560+(I32*20)/550),0),IF(SUM(H32:I32)=0,0,IF(AP32<255,1,ROUND(((H32*20)/520+(I32*20)/450),0)))) -> 1 | AR32: delivery | AW32: =IF(TIMEVALUE(M32)<TIMEVALUE(AJ32),AJ32,M32) -> 11:26:37 | AY32: 3 | BA32: =F32 -> КОВИНСКОЕ-Ш-1К1 | BB32: =AP32*3.5+10*60 -> 1139.7 | BL32: КОРОВИНСКОЕ_Ш-1 Т/ЗАЛ
C33: 154 | D33: 880 | E33: 4880 | F33: ДМИТРОВСКОЕ-Ш-107аК5 | G33: АМ | H33: 7.22 | I33: 3.38 | K33: АВС06_1 | M33: 11:57:08 | N33: 1 | O33: 5 | P33: Москва | Q33: Дмитровское ш.,д.107А к.5 | R33: Петросян Ерванд Айказович | S33: 50ОУ637069 | T33: 89259050666 | U33: ФОРД | V33: К182АМ977 | W33: 9947787533 | X33: Грузовой фургон | Y33: 3Т | Z33: авс | AA33: 8 | AB33: F154 | AC33: Москва, Дмитровское ш.,д.107А к.5 | AF33: 8П | AI33: 2 | AJ33: 09:30 | AK33: 0.5 | AL33: =CONCATENATE(TEXT(AJ33,"ЧЧ:ММ")," ","-"," ",TEXT(AK33,"ЧЧ:ММ")) -> 09:30 - 12:00 | AM33: 2 | AN33: =IF(AP33>1000,(AP33*320),300000) -> 300000 | AO33: TRUE | AP33: =H33*20+I33*20 -> 212 | AQ33: =IF(AP33>520,ROUNDUP(((H33*20)/560+(I33*20)/550),0),IF(SUM(H33:I33)=0,0,IF(AP33<255,1,ROUND(((H33*20)/520+(I33*20)/450),0)))) -> 1 | AR33: delivery | AW33: =IF(TIMEVALUE(M33)<TIMEVALUE(AJ33),AJ33,M33) -> 11:57:08 | AY33: 2 | BA33: =F33 -> ДМИТРОВСКОЕ-Ш-107аК5 | BB33: =AP33*3.5+10*60 -> 1342 | BF33: 10.966667 | BI33: -9.9716667 | BK33: 8.095 | BL33: ДМИТРОВСКОЕ_Ш-107А Т/ЗАЛ
C34: 308 | D34: 862 | E34: 4862 | F34: ДОЛГОПРУДНАЯ-АЛЛЕЯ-14/2 | G34: АМР | H34: 41.35 | I34: 12.08 | K34: АВС06_1 | M34: 12:41:19 | N34: 1 | O34: 6 | P34: Москва | Q34: Долгопрудная аллея, 14/2 | R34: Петросян Ерванд Айказович | S34: 50ОУ637069 | T34: 89259050666 | U34: ФОРД | V34: К182АМ977 | W34: 9947787533 | X34: Грузовой фургон | Y34: 3Т | Z34: авс | AA34: 8 | AB34: F308 | AC34: Москва, Долгопрудная аллея, 14/2 | AF34: 8П | AI34: 2 | AJ34: =IF((WEEKDAY(TODAY(),2))=6,"10:00","09:00") -> 09:00 | AK34: 0.75 | AL34: =CONCATENATE(TEXT(AJ34,"ЧЧ:ММ")," ","-"," ",TEXT(AK34,"ЧЧ:ММ")) -> 09:00 - 18:00 | AM34: 2 | AN34: =IF(AP34>1000,(AP34*320),300000) -> 341952 | AO34: TRUE | AP34: =H34*20+I34*20 -> 1068.6 | AQ34: =IF(AP34>520,ROUNDUP(((H34*20)/560+(I34*20)/550),0),IF(SUM(H34:I34)=0,0,IF(AP34<255,1,ROUND(((H34*20)/520+(I34*20)/450),0)))) -> 2 | AR34: delivery | AW34: =IF(TIMEVALUE(M34)<TIMEVALUE(AJ34),AJ34,M34) -> 12:41:19 | AY34: 3 | BA34: =F34 -> ДОЛГОПРУДНАЯ-АЛЛЕЯ-14/2 | BB34: =AP34*3.5+10*60 -> 4340.1 | BF34: -0.76166667 | BI34: -14.238333 | BL34: Долгопрудная_Аллея-14 т/зал
C35: 288 | D35: 7090 | E35: 4090 | F35: ЕНИСЕЙСКАЯ-17К1 | G35: АМ | H35: 21.82 | I35: 9.94 | J35: 04:30 | K35: АВС07_1 | M35: 09:00 | N35: 1 | O35: 1 | P35: Москва | Q35: Енисейская ул., д.17, кор. 1 | R35: Зограбян Карен Маисович | S35: 3228503509 | T35: 89263455020 | U35: ФОРД | V35: В343АА977 | W35: 9943536090 | X35: Грузовой фургон | Y35: 3Т | Z35: авс | AA35: 8 | AB35: F288 | AC35: Москва, Енисейская ул., д.17, кор. 1 | AF35: 12П | AI35: 1 | AJ35: 09:00 | AK35: 0.4375 | AL35: =CONCATENATE(TEXT(AJ35,"ЧЧ:ММ")," ","-"," ",TEXT(AK35,"ЧЧ:ММ")) -> 09:00 - 10:30 | AM35: 2 | AN35: =IF(AP35>1000,(AP35*320),300000) -> 300000 | AO35: TRUE | AP35: =H35*20+I35*20 -> 635.2 | AQ35: =IF(AP35>520,ROUNDUP(((H35*20)/560+(I35*20)/550),0),IF(SUM(H35:I35)=0,0,IF(AP35<255,1,ROUND(((H35*20)/520+(I35*20)/450),0)))) -> 2 | AR35: delivery | AW35: =IF(TIMEVALUE(M35)<TIMEVALUE(AJ35),AJ35,M35) -> 09:00 | AY35: 1 | BA35: =F35 -> ЕНИСЕЙСКАЯ-17К1 | BB35: =AP35*2.8+10*60 -> 2378.56 | BE35: -0.77466667 | BF35: -10.438 | BI35: -0.33133333 | BL35: ЕНИСЕЙСКАЯ-17/1 Т/ЗАЛ
C36: 294 | D36: 744 | E36: 4744 | F36: ГРЕКОВА-22 | G36: АМ | H36: 12.89 | I36: 5.13 | K36: АВС07_1 | M36: 09:54:28 | N36: 1 | O36: 2 | P36: Москва | Q36: Грекова ул., д.22 | R36: Зограбян Карен Маисович | S36: 3228503509 | T36: 89263455020 | U36: ФОРД | V36: В343АА977 | W36: 9943536090 | X36: Грузовой фургон | Y36: 3Т | Z36: авс | AA36: 8 | AB36: F294 | AC36: Москва, Грекова ул., д.22 | AF36: 14П | AI36: 2 | AJ36: 09:00 | AK36: 0.54166667 | AL36: =CONCATENATE(TEXT(AJ36,"ЧЧ:ММ")," ","-"," ",TEXT(AK36,"ЧЧ:ММ")) -> 09:00 - 13:00 | AM36: 2 | AN36: =IF(AP36>1000,(AP36*320),300000) -> 300000 | AO36: TRUE | AP36: =H36*20+I36*20 -> 360.4 | AQ36: =IF(AP36>520,ROUNDUP(((H36*20)/560+(I36*20)/550),0),IF(SUM(H36:I36)=0,0,IF(AP36<255,1,ROUND(((H36*20)/520+(I36*20)/450),0)))) -> 1 | AR36: delivery | AW36: =IF(TIMEVALUE(M36)<TIMEVALUE(AJ36),AJ36,M36) -> 09:54:28 | AY36: 1 | BA36: =F36 -> ГРЕКОВА-22 | BB36: =AP36*3+10*60 -> 1681.2 | BE36: -26.696667 | BI36: 18.09 | BK36: -1.7933333 | BL36: ГРЕКОВА-22 Т/ЗАЛ
C37: 338 | D37: 25891 | E37: 4891 | F37: МЫТИЩИ-МИРА-37 | G37: АМР | H37: 19.5 | I37: 15.51 | K37: АВС07_1 | M37: 10:41:02 | N37: 1 | O37: 3 | P37: Мытищи | Q37: Мира ул., д.37 | R37: Зограбян Карен Маисович | S37: 3228503509 | T37: 89263455020 | U37: ФОРД | V37: В343АА977 | W37: 9943536090 | X37: Грузовой фургон | Y37: 3Т | Z37: авс | AA37: 8 | AB37: F338 | AC37: Мытищи, Мира ул., д.37 | AF37: 14П | AI37: 2 | AJ37: =IF((WEEKDAY(TODAY(),2))=6,"10:00","09:30") -> 09:30 | AK37: 0.5 | AL37: =CONCATENATE(TEXT(AJ37,"ЧЧ:ММ")," ","-"," ",TEXT(AK37,"ЧЧ:ММ")) -> 09:30 - 12:00 | AM37: 2 | AN37: =IF(AP37>1000,(AP37*320),300000) -> 300000 | AO37: TRUE | AP37: =H37*20+I37*20 -> 700.2 | AQ37: =IF(AP37>520,ROUNDUP(((H37*20)/560+(I37*20)/550),0),IF(SUM(H37:I37)=0,0,IF(AP37<255,1,ROUND(((H37*20)/520+(I37*20)/450),0)))) -> 2 | AR37: delivery | AW37: =IF(TIMEVALUE(M37)<TIMEVALUE(AJ37),AJ37,M37) -> 10:41:02 | AY37: 3 | BA37: =F37 -> МЫТИЩИ-МИРА-37 | BB37: =AP37*3.4+10*60 -> 2980.68 | BG37: -15.327333 | BL37: Мытищи_Мира-37
C38: 339 | D38: 25998 | E38: 4998 | F38: МЫТИЩИ-ЛЕТНАЯ-21/2 | G38: АМР | H38: 16.19 | I38: 9 | K38: АВС07_1 | L38: 2 | M38: 11:43:09 | N38: 1 | O38: 4 | P38: Мытищи | Q38: Летная ул., д.21/2 | R38: Зограбян Карен Маисович | S38: 3228503509 | T38: 89263455020 | U38: ФОРД | V38: В343АА977 | W38: 9943536090 | X38: Грузовой фургон | Y38: 3Т | Z38: авс | AA38: 8 | AB38: F339 | AC38: Мытищи, Летная ул., д.21/2 | AF38: 12П,2Г | AI38: 2 | AJ38: =IF((WEEKDAY(TODAY(),2))=6,"10:00","09:30") -> 09:30 | AK38: 0.58333333 | AL38: =CONCATENATE(TEXT(AJ38,"ЧЧ:ММ")," ","-"," ",TEXT(AK38,"ЧЧ:ММ")) -> 09:30 - 14:00 | AM38: 2 | AN38: =IF(AP38>1000,(AP38*320),300000) -> 300000 | AO38: TRUE | AP38: =H38*20+I38*20 -> 503.8 | AQ38: =IF(AP38>520,ROUNDUP(((H38*20)/560+(I38*20)/550),0),IF(SUM(H38:I38)=0,0,IF(AP38<255,1,ROUND(((H38*20)/520+(I38*20)/450),0)))) -> 1 | AR38: delivery | AW38: =IF(TIMEVALUE(M38)<TIMEVALUE(AJ38),AJ38,M38) -> 11:43:09 | AY38: 3 | BA38: =F38 -> МЫТИЩИ-ЛЕТНАЯ-21/2 | BB38: =AP38*3.5+10*60 -> 2363.3 | BH38: -13.908333 | BJ38: 46.458333 | BL38: Мытищи_Летная-21
C39: 340 | D39: 25992 | E39: 4992 | F39: МЫТИЩИ-ЮБИЛЕЙНАЯ-10 | G39: АМР | H39: 24.38 | I39: 12.63 | K39: АВС07_1 | M39: 12:33:12 | N39: 1 | O39: 5 | P39: Мытищи | Q39: Юбилейная ул., д.10 | R39: Зограбян Карен Маисович | S39: 3228503509 | T39: 89263455020 | U39: ФОРД | V39: В343АА977 | W39: 9943536090 | X39: Грузовой фургон | Y39: 3Т | Z39: авс | AA39: 8 | AB39: F340 | AC39: Мытищи, Юбилейная ул., д.10 | AF39: 12П | AI39: 2 | AJ39: =IF((WEEKDAY(TODAY(),2))=6,"10:00","09:30") -> 09:30 | AK39: =IF(AP39>2000,"15:00",IF(AP39<1000,"16:30","16:00")) -> 16:30 | AL39: =CONCATENATE(TEXT(AJ39,"ЧЧ:ММ")," ","-"," ",TEXT(AK39,"ЧЧ:ММ")) -> 09:30 - 16:30 | AM39: 2 | AN39: =IF(AP39>1000,(AP39*320),300000) -> 300000 | AO39: TRUE | AP39: =H39*20+I39*20 -> 740.2 | AQ39: =IF(AP39>520,ROUNDUP(((H39*20)/560+(I39*20)/550),0),IF(SUM(H39:I39)=0,0,IF(AP39<255,1,ROUND(((H39*20)/520+(I39*20)/450),0)))) -> 2 | AR39: delivery | AW39: =IF(TIMEVALUE(M39)<TIMEVALUE(AJ39),AJ39,M39) -> 12:33:12 | AY39: 2 | BA39: =F39 -> МЫТИЩИ-ЮБИЛЕЙНАЯ-10 | BB39: =AP39*3.5+10*60 -> 3190.7 | BH39: 27.325 | BL39: Мытищи_Юбилейная-10
C40: 200 | D40: 687 | E40: 7687 | F40: МАРШ-РЫБАЛКО-3 | G40: АМ | H40: 23.94 | I40: 5.12 | J40: 04:30 | K40: АВС08_1 | M40: 09:30 | N40: 1 | O40: 1 | P40: Москва | Q40: ул.Маршала Рыбалко. 3 | R40: Худченко Сергей Анатольевич | S40: 9909585204 | T40: 89206969333 | U40: ФОРД | V40: Т708ВК799 | W40: 9941098916 | X40: Грузовой фургон | Y40: 3Т | Z40: авс | AA40: 8 | AB40: F200 | AC40: Москва, РЫБАЛКО МАРШАЛА УЛ. 3 | AF40: 12П | AI40: 2 | AJ40: 09:30 | AK40: 0.54166667 | AL40: =CONCATENATE(TEXT(AJ40,"ЧЧ:ММ")," ","-"," ",TEXT(AK40,"ЧЧ:ММ")) -> 09:30 - 13:00 | AM40: 1 | AN40: =IF(AP40>1000,(AP40*320),300000) -> 300000 | AO40: TRUE | AP40: =H40*20+I40*20 -> 581.2 | AQ40: =IF(AP40>520,ROUNDUP(((H40*20)/560+(I40*20)/550),0),IF(SUM(H40:I40)=0,0,IF(AP40<255,1,ROUND(((H40*20)/520+(I40*20)/450),0)))) -> 2 | AR40: delivery | AW40: =IF(TIMEVALUE(M40)<TIMEVALUE(AJ40),AJ40,M40) -> 09:30 | AY40: 1 | BA40: =F40 -> МАРШ-РЫБАЛКО-3 | BB40: =AP40*3+10*60 -> 2343.6 | BG40: 53.99 | BH40: -23.326667 | BL40: МАРШАЛА РЫБАЛКО-3 Т/ЗАЛ
...

Sheet ДЛЯ ДОМИНО
A1: п/п | B1: Заказ номер | C1: Заказ дата | D1: Док-т подр. | E1: Док-т номер | F1: Док-т дата | G1: Брутто, кг | H1: Номер магазина | I1: Получатель код | J1: Получатель наименование | K1: Маршрут | L1: Рейс номер | M1: Порядок точки | N1: Время загрузки | O1: Время прибытия в магазин | P1: Транспортная компания | Q1: ФИО водителя | R1: В/У водителя | S1: Телефон водителя | T1: Марка автомобиля | U1: Гос.номер автомобиля | V1: Свид. Регистрации автомобиля | W1: Тип ТС | X1: ГрузоподъемностьТС | Y1: Экспедитор | Z1: Ворота | AA1: Довоз | AB1: Возврат | AC1: Количество паллет
A2: 434 | B2: 389.307849 | C2: "23/10/2025" | D2: 309 | E2: "0720903" | F2: "23/10/2025" | G2: 406.06 | H2: 3 | I2: "(01.3)" | J2: БРАТИСЛАВСКАЯ-29К1 | K2: =VLOOKUP($H2,Orders!$D:$Y,8,0) -> 10 | L2: =VLOOKUP($H2,Orders!$D:$Y,11,0) -> 13 | M2: =VLOOKUP($H2,Orders!$D:$Y,12,0) -> 14 | N2: =INDEX(Orders!J:J,MATCH(K2,Orders!K:K,0)) -> 9 | O2: =VLOOKUP($H2,Orders!$D:$Y,10,0) -> 12 | P2: =VLOOKUP($K2,Orders!$K:$Z,16,0) -> 25 | Q2: =VLOOKUP(K2,Orders!$K:$Z,8,0) -> 17 | R2: =VLOOKUP($Q2,Orders!$R:$Z,2,0) -> 18 | S2: =VLOOKUP($Q2,Orders!$R:$Z,3,0) -> 19 | T2: =VLOOKUP($Q2,Orders!$R:$Z,4,0) -> 20 | U2: =VLOOKUP($Q2,Orders!$R:$Z,5,0) -> 21 | V2: =VLOOKUP($Q2,Orders!$R:$Z,6,0) -> 22 | W2: =VLOOKUP($Q2,Orders!$R:$Z,7,0) -> 23 | X2: =VLOOKUP($Q2,Orders!$R:$Z,8,0) -> 24 | AC2: =VLOOKUP($Q2,Orders!$R:$AA,10,0) -> 26
A3: 530 | B3: 389.307935 | C3: "23/10/2025" | D3: 312 | E3: "0462702" | F3: "23/10/2025" | G3: 16.5 | H3: 3 | I3: "(01.3)" | J3: БРАТИСЛАВСКАЯ-29К1 | K3: =VLOOKUP($H3,Orders!$D:$Y,8,0) -> 10 | L3: =VLOOKUP($H3,Orders!$D:$Y,11,0) -> 13 | M3: =VLOOKUP($H3,Orders!$D:$Y,12,0) -> 14 | N3: =INDEX(Orders!J:J,MATCH(K3,Orders!K:K,0)) -> 9 | O3: =VLOOKUP($H3,Orders!$D:$Y,10,0) -> 12 | P3: =VLOOKUP($K3,Orders!$K:$Z,16,0) -> 25 | Q3: =VLOOKUP(K3,Orders!$K:$Z,8,0) -> 17 | R3: =VLOOKUP($Q3,Orders!$R:$Z,2,0) -> 18 | S3: =VLOOKUP($Q3,Orders!$R:$Z,3,0) -> 19 | T3: =VLOOKUP($Q3,Orders!$R:$Z,4,0) -> 20 | U3: =VLOOKUP($Q3,Orders!$R:$Z,5,0) -> 21 | V3: =VLOOKUP($Q3,Orders!$R:$Z,6,0) -> 22 | W3: =VLOOKUP($Q3,Orders!$R:$Z,7,0) -> 23 | X3: =VLOOKUP($Q3,Orders!$R:$Z,8,0) -> 24 | AC3: =VLOOKUP($Q3,Orders!$R:$AA,10,0) -> 26
A4: 531 | B4: 389.307935 | C4: "23/10/2025" | D4: 311 | E4: "0478638" | F4: "23/10/2025" | G4: 15.91 | H4: 3 | I4: "(01.3)" | J4: БРАТИСЛАВСКАЯ-29К1 | K4: =VLOOKUP($H4,Orders!$D:$Y,8,0) -> 10 | L4: =VLOOKUP($H4,Orders!$D:$Y,11,0) -> 13 | M4: =VLOOKUP($H4,Orders!$D:$Y,12,0) -> 14 | N4: =INDEX(Orders!J:J,MATCH(K4,Orders!K:K,0)) -> 9 | O4: =VLOOKUP($H4,Orders!$D:$Y,10,0) -> 12 | P4: =VLOOKUP($K4,Orders!$K:$Z,16,0) -> 25 | Q4: =VLOOKUP(K4,Orders!$K:$Z,8,0) -> 17 | R4: =VLOOKUP($Q4,Orders!$R:$Z,2,0) -> 18 | S4: =VLOOKUP($Q4,Orders!$R:$Z,3,0) -> 19 | T4: =VLOOKUP($Q4,Orders!$R:$Z,4,0) -> 20 | U4: =VLOOKUP($Q4,Orders!$R:$Z,5,0) -> 21 | V4: =VLOOKUP($Q4,Orders!$R:$Z,6,0) -> 22 | W4: =VLOOKUP($Q4,Orders!$R:$Z,7,0) -> 23 | X4: =VLOOKUP($Q4,Orders!$R:$Z,8,0) -> 24 | AC4: =VLOOKUP($Q4,Orders!$R:$AA,10,0) -> 26
A5: 532 | B5: 389.307935 | C5: "23/10/2025" | D5: 309 | E5: "0720979" | F5: "23/10/2025" | G5: 121.21 | H5: 3 | I5: "(01.3)" | J5: БРАТИСЛАВСКАЯ-29К1 | K5: =VLOOKUP($H5,Orders!$D:$Y,8,0) -> 10 | L5: =VLOOKUP($H5,Orders!$D:$Y,11,0) -> 13 | M5: =VLOOKUP($H5,Orders!$D:$Y,12,0) -> 14 | N5: =INDEX(Orders!J:J,MATCH(K5,Orders!K:K,0)) -> 9 | O5: =VLOOKUP($H5,Orders!$D:$Y,10,0) -> 12 | P5: =VLOOKUP($K5,Orders!$K:$Z,16,0) -> 25 | Q5: =VLOOKUP(K5,Orders!$K:$Z,8,0) -> 17 | R5: =VLOOKUP($Q5,Orders!$R:$Z,2,0) -> 18 | S5: =VLOOKUP($Q5,Orders!$R:$Z,3,0) -> 19 | T5: =VLOOKUP($Q5,Orders!$R:$Z,4,0) -> 20 | U5: =VLOOKUP($Q5,Orders!$R:$Z,5,0) -> 21 | V5: =VLOOKUP($Q5,Orders!$R:$Z,6,0) -> 22 | W5: =VLOOKUP($Q5,Orders!$R:$Z,7,0) -> 23 | X5: =VLOOKUP($Q5,Orders!$R:$Z,8,0) -> 24 | AC5: =VLOOKUP($Q5,Orders!$R:$AA,10,0) -> 26
